
2021-03-26 16:38:33,148 INFO: errors [in app.py:507]
2021-03-26 16:43:35,169 INFO: errors [in app.py:516]
2021-03-26 16:43:38,075 ERROR: Exception on /venues [GET] [in /Users/mlab/Documents/fsnd/projects/fyyur/env/lib/python3.8/site-packages/flask/app.py:1891]
Traceback (most recent call last):
  File "/Users/mlab/Documents/fsnd/projects/fyyur/env/lib/python3.8/site-packages/flask/app.py", line 2447, in wsgi_app
    response = self.full_dispatch_request()
  File "/Users/mlab/Documents/fsnd/projects/fyyur/env/lib/python3.8/site-packages/flask/app.py", line 1952, in full_dispatch_request
    rv = self.handle_user_exception(e)
  File "/Users/mlab/Documents/fsnd/projects/fyyur/env/lib/python3.8/site-packages/flask/app.py", line 1821, in handle_user_exception
    reraise(exc_type, exc_value, tb)
  File "/Users/mlab/Documents/fsnd/projects/fyyur/env/lib/python3.8/site-packages/flask/_compat.py", line 39, in reraise
    raise value
  File "/Users/mlab/Documents/fsnd/projects/fyyur/env/lib/python3.8/site-packages/flask/app.py", line 1950, in full_dispatch_request
    rv = self.dispatch_request()
  File "/Users/mlab/Documents/fsnd/projects/fyyur/env/lib/python3.8/site-packages/flask/app.py", line 1936, in dispatch_request
    return self.view_functions[rule.endpoint](**req.view_args)
  File "app.py", line 113, in venues
    return render_template('pages/venues.html', areas=data);
NameError: name 'data' is not defined
2021-03-26 16:44:04,603 ERROR: Exception on /venues [GET] [in /Users/mlab/Documents/fsnd/projects/fyyur/env/lib/python3.8/site-packages/flask/app.py:1891]
Traceback (most recent call last):
  File "/Users/mlab/Documents/fsnd/projects/fyyur/env/lib/python3.8/site-packages/flask/app.py", line 2447, in wsgi_app
    response = self.full_dispatch_request()
  File "/Users/mlab/Documents/fsnd/projects/fyyur/env/lib/python3.8/site-packages/flask/app.py", line 1952, in full_dispatch_request
    rv = self.handle_user_exception(e)
  File "/Users/mlab/Documents/fsnd/projects/fyyur/env/lib/python3.8/site-packages/flask/app.py", line 1821, in handle_user_exception
    reraise(exc_type, exc_value, tb)
  File "/Users/mlab/Documents/fsnd/projects/fyyur/env/lib/python3.8/site-packages/flask/_compat.py", line 39, in reraise
    raise value
  File "/Users/mlab/Documents/fsnd/projects/fyyur/env/lib/python3.8/site-packages/flask/app.py", line 1950, in full_dispatch_request
    rv = self.dispatch_request()
  File "/Users/mlab/Documents/fsnd/projects/fyyur/env/lib/python3.8/site-packages/flask/app.py", line 1936, in dispatch_request
    return self.view_functions[rule.endpoint](**req.view_args)
  File "app.py", line 113, in venues
    return render_template('pages/venues.html', areas=data);
NameError: name 'data' is not defined
2021-03-26 16:44:52,004 INFO: errors [in app.py:516]
2021-03-26 16:45:48,998 INFO: errors [in app.py:517]
2021-03-26 17:46:33,133 INFO: errors [in app.py:524]
2021-03-26 17:46:41,973 INFO: errors [in /Users/mlab/Documents/fsnd/projects/fyyur/starter_code/app.py:524]
2021-03-26 17:46:46,284 INFO: errors [in /Users/mlab/Documents/fsnd/projects/fyyur/starter_code/app.py:524]
2021-03-26 17:47:07,655 INFO: errors [in /Users/mlab/Documents/fsnd/projects/fyyur/starter_code/app.py:524]
2021-03-26 18:05:17,697 INFO: errors [in app.py:524]
2021-03-26 18:05:27,411 INFO: errors [in /Users/mlab/Documents/fsnd/projects/fyyur/starter_code/app.py:524]
2021-03-26 18:05:33,625 INFO: errors [in /Users/mlab/Documents/fsnd/projects/fyyur/starter_code/app.py:524]
2021-03-26 18:21:05,968 INFO: errors [in app.py:524]
2021-03-26 18:21:22,821 INFO: errors [in /Users/mlab/Documents/fsnd/projects/fyyur/starter_code/app.py:524]
2021-03-26 18:21:38,589 INFO: errors [in /Users/mlab/Documents/fsnd/projects/fyyur/starter_code/app.py:524]
2021-03-26 18:21:51,499 INFO: errors [in /Users/mlab/Documents/fsnd/projects/fyyur/starter_code/app.py:524]
2021-03-26 18:22:09,575 INFO: errors [in /Users/mlab/Documents/fsnd/projects/fyyur/starter_code/app.py:518]
2021-03-26 18:22:28,194 INFO: errors [in /Users/mlab/Documents/fsnd/projects/fyyur/starter_code/app.py:518]
2021-03-26 18:22:31,796 INFO: errors [in /Users/mlab/Documents/fsnd/projects/fyyur/starter_code/app.py:518]
