
2021-03-26 16:38:33,148 INFO: errors [in app.py:507]
2021-03-26 16:43:35,169 INFO: errors [in app.py:516]
2021-03-26 16:43:38,075 ERROR: Exception on /venues [GET] [in /Users/mlab/Documents/fsnd/projects/fyyur/env/lib/python3.8/site-packages/flask/app.py:1891]
Traceback (most recent call last):
  File "/Users/mlab/Documents/fsnd/projects/fyyur/env/lib/python3.8/site-packages/flask/app.py", line 2447, in wsgi_app
    response = self.full_dispatch_request()
  File "/Users/mlab/Documents/fsnd/projects/fyyur/env/lib/python3.8/site-packages/flask/app.py", line 1952, in full_dispatch_request
    rv = self.handle_user_exception(e)
  File "/Users/mlab/Documents/fsnd/projects/fyyur/env/lib/python3.8/site-packages/flask/app.py", line 1821, in handle_user_exception
    reraise(exc_type, exc_value, tb)
  File "/Users/mlab/Documents/fsnd/projects/fyyur/env/lib/python3.8/site-packages/flask/_compat.py", line 39, in reraise
    raise value
  File "/Users/mlab/Documents/fsnd/projects/fyyur/env/lib/python3.8/site-packages/flask/app.py", line 1950, in full_dispatch_request
    rv = self.dispatch_request()
  File "/Users/mlab/Documents/fsnd/projects/fyyur/env/lib/python3.8/site-packages/flask/app.py", line 1936, in dispatch_request
    return self.view_functions[rule.endpoint](**req.view_args)
  File "app.py", line 113, in venues
    return render_template('pages/venues.html', areas=data);
NameError: name 'data' is not defined
2021-03-26 16:44:04,603 ERROR: Exception on /venues [GET] [in /Users/mlab/Documents/fsnd/projects/fyyur/env/lib/python3.8/site-packages/flask/app.py:1891]
Traceback (most recent call last):
  File "/Users/mlab/Documents/fsnd/projects/fyyur/env/lib/python3.8/site-packages/flask/app.py", line 2447, in wsgi_app
    response = self.full_dispatch_request()
  File "/Users/mlab/Documents/fsnd/projects/fyyur/env/lib/python3.8/site-packages/flask/app.py", line 1952, in full_dispatch_request
    rv = self.handle_user_exception(e)
  File "/Users/mlab/Documents/fsnd/projects/fyyur/env/lib/python3.8/site-packages/flask/app.py", line 1821, in handle_user_exception
    reraise(exc_type, exc_value, tb)
  File "/Users/mlab/Documents/fsnd/projects/fyyur/env/lib/python3.8/site-packages/flask/_compat.py", line 39, in reraise
    raise value
  File "/Users/mlab/Documents/fsnd/projects/fyyur/env/lib/python3.8/site-packages/flask/app.py", line 1950, in full_dispatch_request
    rv = self.dispatch_request()
  File "/Users/mlab/Documents/fsnd/projects/fyyur/env/lib/python3.8/site-packages/flask/app.py", line 1936, in dispatch_request
    return self.view_functions[rule.endpoint](**req.view_args)
  File "app.py", line 113, in venues
    return render_template('pages/venues.html', areas=data);
NameError: name 'data' is not defined
2021-03-26 16:44:52,004 INFO: errors [in app.py:516]
2021-03-26 16:45:48,998 INFO: errors [in app.py:517]
2021-03-26 17:46:33,133 INFO: errors [in app.py:524]
2021-03-26 17:46:41,973 INFO: errors [in /Users/mlab/Documents/fsnd/projects/fyyur/starter_code/app.py:524]
2021-03-26 17:46:46,284 INFO: errors [in /Users/mlab/Documents/fsnd/projects/fyyur/starter_code/app.py:524]
2021-03-26 17:47:07,655 INFO: errors [in /Users/mlab/Documents/fsnd/projects/fyyur/starter_code/app.py:524]
2021-03-26 18:05:17,697 INFO: errors [in app.py:524]
2021-03-26 18:05:27,411 INFO: errors [in /Users/mlab/Documents/fsnd/projects/fyyur/starter_code/app.py:524]
2021-03-26 18:05:33,625 INFO: errors [in /Users/mlab/Documents/fsnd/projects/fyyur/starter_code/app.py:524]
2021-03-26 18:21:05,968 INFO: errors [in app.py:524]
2021-03-26 18:21:22,821 INFO: errors [in /Users/mlab/Documents/fsnd/projects/fyyur/starter_code/app.py:524]
2021-03-26 18:21:38,589 INFO: errors [in /Users/mlab/Documents/fsnd/projects/fyyur/starter_code/app.py:524]
2021-03-26 18:21:51,499 INFO: errors [in /Users/mlab/Documents/fsnd/projects/fyyur/starter_code/app.py:524]
2021-03-26 18:22:09,575 INFO: errors [in /Users/mlab/Documents/fsnd/projects/fyyur/starter_code/app.py:518]
2021-03-26 18:22:28,194 INFO: errors [in /Users/mlab/Documents/fsnd/projects/fyyur/starter_code/app.py:518]
2021-03-26 18:22:31,796 INFO: errors [in /Users/mlab/Documents/fsnd/projects/fyyur/starter_code/app.py:518]
2021-03-26 18:34:50,459 INFO: errors [in /Users/mlab/Documents/fsnd/projects/fyyur/starter_code/app.py:523]
2021-03-26 18:37:18,876 INFO: errors [in /Users/mlab/Documents/fsnd/projects/fyyur/starter_code/app.py:528]
2021-03-26 19:36:16,459 INFO: errors [in /Users/mlab/Documents/fsnd/projects/fyyur/starter_code/app.py:540]
2021-03-26 19:36:58,671 INFO: errors [in app.py:540]
2021-03-26 19:37:10,520 ERROR: Exception on /venues [GET] [in /Library/Python/3.8/site-packages/flask/app.py:1891]
Traceback (most recent call last):
  File "/Library/Python/3.8/site-packages/flask/app.py", line 2447, in wsgi_app
    response = self.full_dispatch_request()
  File "/Library/Python/3.8/site-packages/flask/app.py", line 1952, in full_dispatch_request
    rv = self.handle_user_exception(e)
  File "/Library/Python/3.8/site-packages/flask/app.py", line 1821, in handle_user_exception
    reraise(exc_type, exc_value, tb)
  File "/Library/Python/3.8/site-packages/flask/_compat.py", line 39, in reraise
    raise value
  File "/Library/Python/3.8/site-packages/flask/app.py", line 1950, in full_dispatch_request
    rv = self.dispatch_request()
  File "/Library/Python/3.8/site-packages/flask/app.py", line 1936, in dispatch_request
    return self.view_functions[rule.endpoint](**req.view_args)
  File "app.py", line 137, in venues
    return render_template('pages/venues.html', areas=data);
NameError: name 'data' is not defined
2021-03-26 19:37:18,896 ERROR: Exception on /artists/5 [GET] [in /Library/Python/3.8/site-packages/flask/app.py:1891]
Traceback (most recent call last):
  File "/Library/Python/3.8/site-packages/flask/app.py", line 2447, in wsgi_app
    response = self.full_dispatch_request()
  File "/Library/Python/3.8/site-packages/flask/app.py", line 1952, in full_dispatch_request
    rv = self.handle_user_exception(e)
  File "/Library/Python/3.8/site-packages/flask/app.py", line 1821, in handle_user_exception
    reraise(exc_type, exc_value, tb)
  File "/Library/Python/3.8/site-packages/flask/_compat.py", line 39, in reraise
    raise value
  File "/Library/Python/3.8/site-packages/flask/app.py", line 1950, in full_dispatch_request
    rv = self.dispatch_request()
  File "/Library/Python/3.8/site-packages/flask/app.py", line 1936, in dispatch_request
    return self.view_functions[rule.endpoint](**req.view_args)
  File "app.py", line 427, in show_artist
    return render_template('forms/edit_venue.html', form=form, venue=venue)
NameError: name 'form' is not defined
2021-03-26 19:38:37,003 ERROR: Exception on /venues [GET] [in /Library/Python/3.8/site-packages/flask/app.py:1891]
Traceback (most recent call last):
  File "/Library/Python/3.8/site-packages/flask/app.py", line 2447, in wsgi_app
    response = self.full_dispatch_request()
  File "/Library/Python/3.8/site-packages/flask/app.py", line 1952, in full_dispatch_request
    rv = self.handle_user_exception(e)
  File "/Library/Python/3.8/site-packages/flask/app.py", line 1821, in handle_user_exception
    reraise(exc_type, exc_value, tb)
  File "/Library/Python/3.8/site-packages/flask/_compat.py", line 39, in reraise
    raise value
  File "/Library/Python/3.8/site-packages/flask/app.py", line 1950, in full_dispatch_request
    rv = self.dispatch_request()
  File "/Library/Python/3.8/site-packages/flask/app.py", line 1936, in dispatch_request
    return self.view_functions[rule.endpoint](**req.view_args)
  File "app.py", line 137, in venues
    return render_template('pages/venues.html', areas=data);
NameError: name 'data' is not defined
2021-03-26 19:38:48,705 INFO: errors [in app.py:544]
2021-03-26 19:39:05,776 ERROR: Exception on /artists [GET] [in /Library/Python/3.8/site-packages/flask/app.py:1891]
Traceback (most recent call last):
  File "/Library/Python/3.8/site-packages/flask/app.py", line 2447, in wsgi_app
    response = self.full_dispatch_request()
  File "/Library/Python/3.8/site-packages/flask/app.py", line 1952, in full_dispatch_request
    rv = self.handle_user_exception(e)
  File "/Library/Python/3.8/site-packages/flask/app.py", line 1821, in handle_user_exception
    reraise(exc_type, exc_value, tb)
  File "/Library/Python/3.8/site-packages/flask/_compat.py", line 39, in reraise
    raise value
  File "/Library/Python/3.8/site-packages/flask/app.py", line 1950, in full_dispatch_request
    rv = self.dispatch_request()
  File "/Library/Python/3.8/site-packages/flask/app.py", line 1936, in dispatch_request
    return self.view_functions[rule.endpoint](**req.view_args)
  File "app.py", line 286, in artists
    return render_template('pages/artists.html', artists=data)
NameError: name 'data' is not defined
2021-03-26 19:39:07,320 ERROR: Exception on /venues [GET] [in /Library/Python/3.8/site-packages/flask/app.py:1891]
Traceback (most recent call last):
  File "/Library/Python/3.8/site-packages/flask/app.py", line 2447, in wsgi_app
    response = self.full_dispatch_request()
  File "/Library/Python/3.8/site-packages/flask/app.py", line 1952, in full_dispatch_request
    rv = self.handle_user_exception(e)
  File "/Library/Python/3.8/site-packages/flask/app.py", line 1821, in handle_user_exception
    reraise(exc_type, exc_value, tb)
  File "/Library/Python/3.8/site-packages/flask/_compat.py", line 39, in reraise
    raise value
  File "/Library/Python/3.8/site-packages/flask/app.py", line 1950, in full_dispatch_request
    rv = self.dispatch_request()
  File "/Library/Python/3.8/site-packages/flask/app.py", line 1936, in dispatch_request
    return self.view_functions[rule.endpoint](**req.view_args)
  File "app.py", line 137, in venues
    return render_template('pages/venues.html', areas=data);
NameError: name 'data' is not defined
2021-03-26 19:39:08,171 ERROR: Exception on /shows [GET] [in /Library/Python/3.8/site-packages/flask/app.py:1891]
Traceback (most recent call last):
  File "/Library/Python/3.8/site-packages/flask/app.py", line 2447, in wsgi_app
    response = self.full_dispatch_request()
  File "/Library/Python/3.8/site-packages/flask/app.py", line 1952, in full_dispatch_request
    rv = self.handle_user_exception(e)
  File "/Library/Python/3.8/site-packages/flask/app.py", line 1821, in handle_user_exception
    reraise(exc_type, exc_value, tb)
  File "/Library/Python/3.8/site-packages/flask/_compat.py", line 39, in reraise
    raise value
  File "/Library/Python/3.8/site-packages/flask/app.py", line 1950, in full_dispatch_request
    rv = self.dispatch_request()
  File "/Library/Python/3.8/site-packages/flask/app.py", line 1936, in dispatch_request
    return self.view_functions[rule.endpoint](**req.view_args)
  File "app.py", line 507, in shows
    return render_template('pages/shows.html', shows=data)
NameError: name 'data' is not defined
2021-03-26 19:39:10,001 ERROR: Exception on /venues [GET] [in /Library/Python/3.8/site-packages/flask/app.py:1891]
Traceback (most recent call last):
  File "/Library/Python/3.8/site-packages/flask/app.py", line 2447, in wsgi_app
    response = self.full_dispatch_request()
  File "/Library/Python/3.8/site-packages/flask/app.py", line 1952, in full_dispatch_request
    rv = self.handle_user_exception(e)
  File "/Library/Python/3.8/site-packages/flask/app.py", line 1821, in handle_user_exception
    reraise(exc_type, exc_value, tb)
  File "/Library/Python/3.8/site-packages/flask/_compat.py", line 39, in reraise
    raise value
  File "/Library/Python/3.8/site-packages/flask/app.py", line 1950, in full_dispatch_request
    rv = self.dispatch_request()
  File "/Library/Python/3.8/site-packages/flask/app.py", line 1936, in dispatch_request
    return self.view_functions[rule.endpoint](**req.view_args)
  File "app.py", line 137, in venues
    return render_template('pages/venues.html', areas=data);
NameError: name 'data' is not defined
2021-03-26 19:39:11,207 ERROR: Exception on /artists [GET] [in /Library/Python/3.8/site-packages/flask/app.py:1891]
Traceback (most recent call last):
  File "/Library/Python/3.8/site-packages/flask/app.py", line 2447, in wsgi_app
    response = self.full_dispatch_request()
  File "/Library/Python/3.8/site-packages/flask/app.py", line 1952, in full_dispatch_request
    rv = self.handle_user_exception(e)
  File "/Library/Python/3.8/site-packages/flask/app.py", line 1821, in handle_user_exception
    reraise(exc_type, exc_value, tb)
  File "/Library/Python/3.8/site-packages/flask/_compat.py", line 39, in reraise
    raise value
  File "/Library/Python/3.8/site-packages/flask/app.py", line 1950, in full_dispatch_request
    rv = self.dispatch_request()
  File "/Library/Python/3.8/site-packages/flask/app.py", line 1936, in dispatch_request
    return self.view_functions[rule.endpoint](**req.view_args)
  File "app.py", line 286, in artists
    return render_template('pages/artists.html', artists=data)
NameError: name 'data' is not defined
2021-03-26 19:39:12,026 ERROR: Exception on /shows [GET] [in /Library/Python/3.8/site-packages/flask/app.py:1891]
Traceback (most recent call last):
  File "/Library/Python/3.8/site-packages/flask/app.py", line 2447, in wsgi_app
    response = self.full_dispatch_request()
  File "/Library/Python/3.8/site-packages/flask/app.py", line 1952, in full_dispatch_request
    rv = self.handle_user_exception(e)
  File "/Library/Python/3.8/site-packages/flask/app.py", line 1821, in handle_user_exception
    reraise(exc_type, exc_value, tb)
  File "/Library/Python/3.8/site-packages/flask/_compat.py", line 39, in reraise
    raise value
  File "/Library/Python/3.8/site-packages/flask/app.py", line 1950, in full_dispatch_request
    rv = self.dispatch_request()
  File "/Library/Python/3.8/site-packages/flask/app.py", line 1936, in dispatch_request
    return self.view_functions[rule.endpoint](**req.view_args)
  File "app.py", line 507, in shows
    return render_template('pages/shows.html', shows=data)
NameError: name 'data' is not defined
2021-03-26 19:42:14,076 INFO: errors [in /Users/mlab/Documents/fsnd/projects/fyyur/starter_code/app.py:551]
2021-03-26 20:25:54,101 INFO: errors [in app.py:276]
2021-03-26 20:25:59,221 ERROR: Exception on /venues [GET] [in /Library/Python/3.8/site-packages/flask/app.py:1891]
Traceback (most recent call last):
  File "/Library/Python/3.8/site-packages/flask/app.py", line 2447, in wsgi_app
    response = self.full_dispatch_request()
  File "/Library/Python/3.8/site-packages/flask/app.py", line 1952, in full_dispatch_request
    rv = self.handle_user_exception(e)
  File "/Library/Python/3.8/site-packages/flask/app.py", line 1821, in handle_user_exception
    reraise(exc_type, exc_value, tb)
  File "/Library/Python/3.8/site-packages/flask/_compat.py", line 39, in reraise
    raise value
  File "/Library/Python/3.8/site-packages/flask/app.py", line 1950, in full_dispatch_request
    rv = self.dispatch_request()
  File "/Library/Python/3.8/site-packages/flask/app.py", line 1936, in dispatch_request
    return self.view_functions[rule.endpoint](**req.view_args)
  File "app.py", line 123, in venues
    return render_template('pages/venues.html', areas=data);
NameError: name 'data' is not defined
2021-03-26 20:26:13,740 ERROR: Exception on /venues/create [GET] [in /Library/Python/3.8/site-packages/flask/app.py:1891]
Traceback (most recent call last):
  File "/Library/Python/3.8/site-packages/flask/app.py", line 2447, in wsgi_app
    response = self.full_dispatch_request()
  File "/Library/Python/3.8/site-packages/flask/app.py", line 1952, in full_dispatch_request
    rv = self.handle_user_exception(e)
  File "/Library/Python/3.8/site-packages/flask/app.py", line 1821, in handle_user_exception
    reraise(exc_type, exc_value, tb)
  File "/Library/Python/3.8/site-packages/flask/_compat.py", line 39, in reraise
    raise value
  File "/Library/Python/3.8/site-packages/flask/app.py", line 1950, in full_dispatch_request
    rv = self.dispatch_request()
  File "/Library/Python/3.8/site-packages/flask/app.py", line 1936, in dispatch_request
    return self.view_functions[rule.endpoint](**req.view_args)
  File "app.py", line 150, in create_venue_form
    form = VenueForm()
  File "/Users/mlab/Library/Python/3.8/lib/python/site-packages/wtforms/form.py", line 208, in __call__
    return type.__call__(cls, *args, **kwargs)
  File "/Users/mlab/Library/Python/3.8/lib/python/site-packages/flask_wtf/form.py", line 157, in __init__
    super(Form, self).__init__(*args, **kwargs)
  File "/Users/mlab/Library/Python/3.8/lib/python/site-packages/flask_wtf/form.py", line 87, in __init__
    super(FlaskForm, self).__init__(formdata=formdata, **kwargs)
  File "/Users/mlab/Library/Python/3.8/lib/python/site-packages/wtforms/form.py", line 274, in __init__
    self.process(formdata, obj, data=data, **kwargs)
  File "/Users/mlab/Library/Python/3.8/lib/python/site-packages/wtforms/form.py", line 131, in process
    field.process(formdata)
  File "/Users/mlab/Library/Python/3.8/lib/python/site-packages/wtforms/csrf/core.py", line 43, in process
    self.current_token = self.csrf_impl.generate_csrf_token(self)
  File "/Users/mlab/Library/Python/3.8/lib/python/site-packages/flask_wtf/csrf.py", line 139, in generate_csrf_token
    return generate_csrf(
  File "/Users/mlab/Library/Python/3.8/lib/python/site-packages/flask_wtf/csrf.py", line 33, in generate_csrf
    secret_key = _get_config(
  File "/Users/mlab/Library/Python/3.8/lib/python/site-packages/flask_wtf/csrf.py", line 128, in _get_config
    raise RuntimeError(message)
RuntimeError: A secret key is required to use CSRF.
2021-03-26 20:26:16,660 ERROR: Exception on /shows/create [GET] [in /Library/Python/3.8/site-packages/flask/app.py:1891]
Traceback (most recent call last):
  File "/Library/Python/3.8/site-packages/flask/app.py", line 2447, in wsgi_app
    response = self.full_dispatch_request()
  File "/Library/Python/3.8/site-packages/flask/app.py", line 1952, in full_dispatch_request
    rv = self.handle_user_exception(e)
  File "/Library/Python/3.8/site-packages/flask/app.py", line 1821, in handle_user_exception
    reraise(exc_type, exc_value, tb)
  File "/Library/Python/3.8/site-packages/flask/_compat.py", line 39, in reraise
    raise value
  File "/Library/Python/3.8/site-packages/flask/app.py", line 1950, in full_dispatch_request
    rv = self.dispatch_request()
  File "/Library/Python/3.8/site-packages/flask/app.py", line 1936, in dispatch_request
    return self.view_functions[rule.endpoint](**req.view_args)
  File "app.py", line 244, in create_shows
    form = ShowForm()
  File "/Users/mlab/Library/Python/3.8/lib/python/site-packages/wtforms/form.py", line 208, in __call__
    return type.__call__(cls, *args, **kwargs)
  File "/Users/mlab/Library/Python/3.8/lib/python/site-packages/flask_wtf/form.py", line 157, in __init__
    super(Form, self).__init__(*args, **kwargs)
  File "/Users/mlab/Library/Python/3.8/lib/python/site-packages/flask_wtf/form.py", line 87, in __init__
    super(FlaskForm, self).__init__(formdata=formdata, **kwargs)
  File "/Users/mlab/Library/Python/3.8/lib/python/site-packages/wtforms/form.py", line 274, in __init__
    self.process(formdata, obj, data=data, **kwargs)
  File "/Users/mlab/Library/Python/3.8/lib/python/site-packages/wtforms/form.py", line 131, in process
    field.process(formdata)
  File "/Users/mlab/Library/Python/3.8/lib/python/site-packages/wtforms/csrf/core.py", line 43, in process
    self.current_token = self.csrf_impl.generate_csrf_token(self)
  File "/Users/mlab/Library/Python/3.8/lib/python/site-packages/flask_wtf/csrf.py", line 139, in generate_csrf_token
    return generate_csrf(
  File "/Users/mlab/Library/Python/3.8/lib/python/site-packages/flask_wtf/csrf.py", line 33, in generate_csrf
    secret_key = _get_config(
  File "/Users/mlab/Library/Python/3.8/lib/python/site-packages/flask_wtf/csrf.py", line 128, in _get_config
    raise RuntimeError(message)
RuntimeError: A secret key is required to use CSRF.
2021-03-26 20:26:20,951 ERROR: Exception on /venues [GET] [in /Library/Python/3.8/site-packages/flask/app.py:1891]
Traceback (most recent call last):
  File "/Library/Python/3.8/site-packages/flask/app.py", line 2447, in wsgi_app
    response = self.full_dispatch_request()
  File "/Library/Python/3.8/site-packages/flask/app.py", line 1952, in full_dispatch_request
    rv = self.handle_user_exception(e)
  File "/Library/Python/3.8/site-packages/flask/app.py", line 1821, in handle_user_exception
    reraise(exc_type, exc_value, tb)
  File "/Library/Python/3.8/site-packages/flask/_compat.py", line 39, in reraise
    raise value
  File "/Library/Python/3.8/site-packages/flask/app.py", line 1950, in full_dispatch_request
    rv = self.dispatch_request()
  File "/Library/Python/3.8/site-packages/flask/app.py", line 1936, in dispatch_request
    return self.view_functions[rule.endpoint](**req.view_args)
  File "app.py", line 123, in venues
    return render_template('pages/venues.html', areas=data);
NameError: name 'data' is not defined
2021-03-26 20:26:22,213 ERROR: Exception on /artists [GET] [in /Library/Python/3.8/site-packages/flask/app.py:1891]
Traceback (most recent call last):
  File "/Library/Python/3.8/site-packages/flask/app.py", line 2447, in wsgi_app
    response = self.full_dispatch_request()
  File "/Library/Python/3.8/site-packages/flask/app.py", line 1952, in full_dispatch_request
    rv = self.handle_user_exception(e)
  File "/Library/Python/3.8/site-packages/flask/app.py", line 1821, in handle_user_exception
    reraise(exc_type, exc_value, tb)
  File "/Library/Python/3.8/site-packages/flask/_compat.py", line 39, in reraise
    raise value
  File "/Library/Python/3.8/site-packages/flask/app.py", line 1950, in full_dispatch_request
    rv = self.dispatch_request()
  File "/Library/Python/3.8/site-packages/flask/app.py", line 1936, in dispatch_request
    return self.view_functions[rule.endpoint](**req.view_args)
  File "app.py", line 179, in artists
    return render_template('pages/artists.html', artists=data)
NameError: name 'data' is not defined
2021-03-26 20:26:22,974 ERROR: Exception on /shows [GET] [in /Library/Python/3.8/site-packages/flask/app.py:1891]
Traceback (most recent call last):
  File "/Library/Python/3.8/site-packages/flask/app.py", line 2447, in wsgi_app
    response = self.full_dispatch_request()
  File "/Library/Python/3.8/site-packages/flask/app.py", line 1952, in full_dispatch_request
    rv = self.handle_user_exception(e)
  File "/Library/Python/3.8/site-packages/flask/app.py", line 1821, in handle_user_exception
    reraise(exc_type, exc_value, tb)
  File "/Library/Python/3.8/site-packages/flask/_compat.py", line 39, in reraise
    raise value
  File "/Library/Python/3.8/site-packages/flask/app.py", line 1950, in full_dispatch_request
    rv = self.dispatch_request()
  File "/Library/Python/3.8/site-packages/flask/app.py", line 1936, in dispatch_request
    return self.view_functions[rule.endpoint](**req.view_args)
  File "app.py", line 239, in shows
    return render_template('pages/shows.html', shows=data)
NameError: name 'data' is not defined
2021-03-30 22:38:37,379 INFO: errors [in app.py:275]
